{
 "cells": [
  {
   "cell_type": "markdown",
   "metadata": {},
   "source": [
    "### Dict vs TypedDict vs Pydantic"
   ]
  },
  {
   "cell_type": "code",
   "execution_count": 1,
   "metadata": {},
   "outputs": [],
   "source": [
    "person = {\"name\": \"Alice\", \"age\": 30}\n",
    "person2 = {\"name\": \"John\", \"Age\": 50, \"job_title\": \"Manager\"}"
   ]
  },
  {
   "cell_type": "code",
   "execution_count": 2,
   "metadata": {},
   "outputs": [],
   "source": [
    "from typing import TypedDict\n",
    "\n",
    "\n",
    "class Person(TypedDict):\n",
    "    name: str\n",
    "    age: int\n",
    "\n",
    "\n",
    "person: Person = {\n",
    "    \"name\": \"Alice\",\n",
    "    \"age\": \"wrong\",\n",
    "}  # Type-safe dictionary, static linters like mypy can detect this"
   ]
  },
  {
   "cell_type": "code",
   "execution_count": 3,
   "metadata": {},
   "outputs": [],
   "source": [
    "person2: Person = {\"name\": \"John\", \"Age\": 50, \"job_title\": \"Manager\"}"
   ]
  },
  {
   "cell_type": "code",
   "execution_count": 4,
   "metadata": {},
   "outputs": [
    {
     "ename": "ValidationError",
     "evalue": "1 validation error for Person\nage\n  Input should be a valid integer, unable to parse string as an integer [type=int_parsing, input_value='wrong', input_type=str]\n    For further information visit https://errors.pydantic.dev/2.9/v/int_parsing",
     "output_type": "error",
     "traceback": [
      "\u001b[1;31m---------------------------------------------------------------------------\u001b[0m",
      "\u001b[1;31mValidationError\u001b[0m                           Traceback (most recent call last)",
      "Cell \u001b[1;32mIn[4], line 9\u001b[0m\n\u001b[0;32m      5\u001b[0m     name: \u001b[38;5;28mstr\u001b[39m\n\u001b[0;32m      6\u001b[0m     age: \u001b[38;5;28mint\u001b[39m\n\u001b[1;32m----> 9\u001b[0m person \u001b[38;5;241m=\u001b[39m \u001b[43mPerson\u001b[49m\u001b[43m(\u001b[49m\u001b[43mname\u001b[49m\u001b[38;5;241;43m=\u001b[39;49m\u001b[38;5;124;43m\"\u001b[39;49m\u001b[38;5;124;43mAlice\u001b[39;49m\u001b[38;5;124;43m\"\u001b[39;49m\u001b[43m,\u001b[49m\u001b[43m \u001b[49m\u001b[43mage\u001b[49m\u001b[38;5;241;43m=\u001b[39;49m\u001b[38;5;124;43m\"\u001b[39;49m\u001b[38;5;124;43mwrong\u001b[39;49m\u001b[38;5;124;43m\"\u001b[39;49m\u001b[43m)\u001b[49m  \u001b[38;5;66;03m# Validated model with data parsing\u001b[39;00m\n",
      "File \u001b[1;32mc:\\Users\\Asus\\Documents\\LangGraph Course\\VE_lang\\Lib\\site-packages\\pydantic\\main.py:212\u001b[0m, in \u001b[0;36mBaseModel.__init__\u001b[1;34m(self, **data)\u001b[0m\n\u001b[0;32m    210\u001b[0m \u001b[38;5;66;03m# `__tracebackhide__` tells pytest and some other tools to omit this function from tracebacks\u001b[39;00m\n\u001b[0;32m    211\u001b[0m __tracebackhide__ \u001b[38;5;241m=\u001b[39m \u001b[38;5;28;01mTrue\u001b[39;00m\n\u001b[1;32m--> 212\u001b[0m validated_self \u001b[38;5;241m=\u001b[39m \u001b[38;5;28;43mself\u001b[39;49m\u001b[38;5;241;43m.\u001b[39;49m\u001b[43m__pydantic_validator__\u001b[49m\u001b[38;5;241;43m.\u001b[39;49m\u001b[43mvalidate_python\u001b[49m\u001b[43m(\u001b[49m\u001b[43mdata\u001b[49m\u001b[43m,\u001b[49m\u001b[43m \u001b[49m\u001b[43mself_instance\u001b[49m\u001b[38;5;241;43m=\u001b[39;49m\u001b[38;5;28;43mself\u001b[39;49m\u001b[43m)\u001b[49m\n\u001b[0;32m    213\u001b[0m \u001b[38;5;28;01mif\u001b[39;00m \u001b[38;5;28mself\u001b[39m \u001b[38;5;129;01mis\u001b[39;00m \u001b[38;5;129;01mnot\u001b[39;00m validated_self:\n\u001b[0;32m    214\u001b[0m     warnings\u001b[38;5;241m.\u001b[39mwarn(\n\u001b[0;32m    215\u001b[0m         \u001b[38;5;124m'\u001b[39m\u001b[38;5;124mA custom validator is returning a value other than `self`.\u001b[39m\u001b[38;5;130;01m\\n\u001b[39;00m\u001b[38;5;124m'\u001b[39m\n\u001b[0;32m    216\u001b[0m         \u001b[38;5;124m\"\u001b[39m\u001b[38;5;124mReturning anything other than `self` from a top level model validator isn\u001b[39m\u001b[38;5;124m'\u001b[39m\u001b[38;5;124mt supported when validating via `__init__`.\u001b[39m\u001b[38;5;130;01m\\n\u001b[39;00m\u001b[38;5;124m\"\u001b[39m\n\u001b[0;32m    217\u001b[0m         \u001b[38;5;124m'\u001b[39m\u001b[38;5;124mSee the `model_validator` docs (https://docs.pydantic.dev/latest/concepts/validators/#model-validators) for more details.\u001b[39m\u001b[38;5;124m'\u001b[39m,\n\u001b[0;32m    218\u001b[0m         category\u001b[38;5;241m=\u001b[39m\u001b[38;5;28;01mNone\u001b[39;00m,\n\u001b[0;32m    219\u001b[0m     )\n",
      "\u001b[1;31mValidationError\u001b[0m: 1 validation error for Person\nage\n  Input should be a valid integer, unable to parse string as an integer [type=int_parsing, input_value='wrong', input_type=str]\n    For further information visit https://errors.pydantic.dev/2.9/v/int_parsing"
     ]
    }
   ],
   "source": [
    "from pydantic import BaseModel\n",
    "\n",
    "\n",
    "class Person(BaseModel):\n",
    "    name: str\n",
    "    age: int\n",
    "\n",
    "\n",
    "person = Person(name=\"Alice\", age=\"wrong\")  # Validated model with data parsing"
   ]
  },
  {
   "cell_type": "code",
   "execution_count": null,
   "metadata": {},
   "outputs": [],
   "source": []
  }
 ],
 "metadata": {
  "kernelspec": {
   "display_name": "VE_lang",
   "language": "python",
   "name": "python3"
  },
  "language_info": {
   "codemirror_mode": {
    "name": "ipython",
    "version": 3
   },
   "file_extension": ".py",
   "mimetype": "text/x-python",
   "name": "python",
   "nbconvert_exporter": "python",
   "pygments_lexer": "ipython3",
   "version": "3.11.5"
  }
 },
 "nbformat": 4,
 "nbformat_minor": 2
}
